I'm sorry, but an uncaught exception occurred.

While running game code:
  File "game/second_task.rpy", line 169, in script call
    call what_chosen('салат "Цезарь"\n300р') from _call_what_chosen_3
  File "game/second_task.rpy", line 236, in script call
    call answer_if_interesting(True, 1, "Это прелестно. Я рад, что смог привить тебе любовь к своей профессии.") from _call_answer_if_interesting
  File "game/third_task.rpy", line 35, in script call
    call award_character(result[-2:]) from _call_award_character
  File "game/third_task.rpy", line 35, in script call
    call award_character(result[-2:]) from _call_award_character
  File "game/third_task.rpy", line 35, in script call
    call award_character(result[-2:]) from _call_award_character
  File "game/third_task.rpy", line 92, in script
    main_character "[variations[16]], что мне пригодятся эти знания!"
IndexError: list index out of range

-- Full Traceback ------------------------------------------------------------

Full traceback:
  File "game/second_task.rpy", line 169, in script call
    call what_chosen('салат "Цезарь"\n300р') from _call_what_chosen_3
  File "game/second_task.rpy", line 236, in script call
    call answer_if_interesting(True, 1, "Это прелестно. Я рад, что смог привить тебе любовь к своей профессии.") from _call_answer_if_interesting
  File "game/third_task.rpy", line 35, in script call
    call award_character(result[-2:]) from _call_award_character
  File "game/third_task.rpy", line 35, in script call
    call award_character(result[-2:]) from _call_award_character
  File "game/third_task.rpy", line 35, in script call
    call award_character(result[-2:]) from _call_award_character
  File "game/third_task.rpy", line 92, in script
    main_character "[variations[16]], что мне пригодятся эти знания!"
  File "C:\renpy\renpy_inst\inner\renpy\ast.py", line 921, in execute
    renpy.exports.say(who, what, *args, **kwargs)
  File "C:\renpy\renpy_inst\inner\renpy\exports.py", line 1373, in say
    who(what, *args, **kwargs)
  File "C:\renpy\renpy_inst\inner\renpy\character.py", line 1253, in __call__
    what = self.prefix_suffix("what", self.what_prefix, what, self.what_suffix)
  File "C:\renpy\renpy_inst\inner\renpy\character.py", line 1172, in prefix_suffix
    return (sub(prefix) + sub(body) + sub(suffix))
  File "C:\renpy\renpy_inst\inner\renpy\character.py", line 1152, in sub
    return renpy.substitutions.substitute(s, scope=scope, force=force, translate=translate)[0]
  File "C:\renpy\renpy_inst\inner\renpy\substitutions.py", line 278, in substitute
    s = formatter.vformat(s, (), kwargs) # type: ignore
  File "/home/tom/ab/renpy-build/tmp/install.linux-x86_64/lib/python3.9/string.py", line 165, in vformat
  File "/home/tom/ab/renpy-build/tmp/install.linux-x86_64/lib/python3.9/string.py", line 205, in _vformat
  File "C:\renpy\renpy_inst\inner\renpy\substitutions.py", line 168, in get_field
    obj, arg_used = super(Formatter, self).get_field(field_name, args, kwargs)
  File "/home/tom/ab/renpy-build/tmp/install.linux-x86_64/lib/python3.9/string.py", line 278, in get_field
  File "C:\renpy\renpy_inst\inner\renpy\revertable.py", line 217, in __getitem__
    rv = list.__getitem__(self, index)
IndexError: list index out of range

Windows-10-10.0.19044 AMD64
Ren'Py 8.0.3.22090809
Пушистые IT 0.0
Wed Dec 14 15:58:26 2022
